Workbook

Sheet Calculation
A1: Capital Walk- On Notice of Offer of Possession | B1: Column1
A2: Business Unit | B2: =_xlfn.IFNA(VLOOKUP($B$3,[1]Final!$B:$AF,3,0),0) -> M3M Capital Walk in M3M Capital Phase-1
A3: Unit No | B3: R1 165
A4: Collection RM | B4: =VLOOKUP($B$3,'OOP Cases'!$A:$BZ,77,0) -> Priya Anand
A5: Frontend RM | B5: =VLOOKUP($B$3,'OOP Cases'!$A:$BZ,78,0) -> Sabhyata Kapoor
A6: Customer Name | B6: =_xlfn.IFNA(VLOOKUP($B$3,'OOP Cases'!$A:$BW,5,0),0) -> Mr. SHUBHAM SINGH
A7: Schedule | B7: On Notice of Offer of Possession
A8: Invoice Date | B8: =_xlfn.IFNA(VLOOKUP($B$3,'OOP Cases'!$A:$BW,59,0),0) -> 46176
A9: Due Date | B9: =_xlfn.IFNA(VLOOKUP($B$3,'OOP Cases'!$A:$BW,60,0),0) -> 46206
A10: OLD Basic Sales Price | B10: =_xlfn.IFNA(VLOOKUP($B$3,'OOP Cases'!$A:$BW,19,0),0) -> 4870725
A11: New Basic Sales Price | B11: =_xlfn.IFNA(VLOOKUP($B$3,'OOP Cases'!$A:$BW,26,0),0) -> 4870725
A12: Old Area | B12: =_xlfn.IFNA(VLOOKUP($B$3,'OOP Cases'!$A:$BW,10,0),0) -> 649.43
A13: New Area | B13: =_xlfn.IFNA(VLOOKUP($B$3,'OOP Cases'!$A:$BW,11,0),0) -> 649.43
A14: Difference In Area | B14: =_xlfn.IFNA(VLOOKUP($B$3,'OOP Cases'!$A:$BW,12,0),0) -> 0
A15: Discount/Credit Note (Already applied) | B15: =_xlfn.IFNA(VLOOKUP($B$3,'OOP Cases'!$A:$BW,27,0)+VLOOKUP($B$3,'OOP Cases'!$A:$BW,28,0),0) -> 0
A16: PBIC after Increase or Decrease Area | B16: =_xlfn.IFNA(VLOOKUP($B$3,'OOP Cases'!$A:$BW,35,0),0) -> 77985
A17: Total BSP & PBIC | B17: =_xlfn.IFNA(VLOOKUP($B$3,'OOP Cases'!$A:$BW,39,0),0) -> 4948710
A18: Total GST on BSP/ PBIC | B18: =_xlfn.IFNA(VLOOKUP($B$3,'OOP Cases'!$A:$BW,40,0),0) -> 257574
A19: IFMS Amount after Change Area | B19: =_xlfn.IFNA(VLOOKUP($B$3,'OOP Cases'!$A:$BW,38,0),0) -> 77985
A20: Total Amount | B20: =_xlfn.IFNA(VLOOKUP($B$3,'OOP Cases'!$A:$BW,42,0),0) -> 5284269
A21: Total Received | B21: =_xlfn.IFNA(VLOOKUP($B$3,'OOP Cases'!$A:$BW,43,0),0) -> 4653102
A22: Total Payable Without Interest | B22: =B20-B21-B23 -> 631167
A23: Interest Due | B23: =_xlfn.IFNA(VLOOKUP($B$3,'OOP Cases'!$A:$BW,44,0),0) -> 0
A24: Total Accumulation (Subject to Payment demand received within Due Date) | B24: =_xlfn.IFNA(VLOOKUP($B$3,'OOP Cases'!$A:$BX,76,0),0) -> 0
A25: Payable With Interest | B25: =_xlfn.IFNA(VLOOKUP($B$3,'OOP Cases'!$A:$BW,45,0),0) -> 631167
A26: Net Amount Payable With Interest | B26: =B25-B24 -> 631167
A27: * 1% To avoid penal consequences under the Income Tax Act 1961, you are required to comply with provisions of Section 194 IA
A28: (effective from 01st June 2013), by deducting TDS @ 1% from each instalment/payment. Please submit with us TDS certificate/Challan
A29: showing proof of deposition of the same within 7 days from the date of tax so deposited so that the appropriate credit may be allowed in your account
A30: * Stamp Duty Charges is payable extra

Sheet OOP Cases
A1: Unit No | B1: Business Unit | C1: Booking No | D1: Application No | E1: Customer Name | F1: Booking Date | G1: Block | H1: Floor | I1: Hierarchy Level 4 | J1: Suer Area (Sq. ft.) | K1: New Super Area (Sq. ft.) | L1: Diff in Super Area | M1: Carpet Area (Sq. ft.) | N1: New Carpet Area (Sq. ft.) | O1: Diff in Carpet Area Area | P1: Super Area Rate (Booking Rate) | Q1: Carpet Area Rate (Booking Rate) | R1: Current Rate | S1: BSP | T1: GST on BSP as per Old Area | U1: GST%age | V1: Increase/Decrease Area cost | W1: GST% on Increase/Decrease Area cost | X1: Increased Unit Cost due to Excess Discount_Basic | Y1: Increased Unit Cost due to Excess Discount_Tax | Z1: BASIC after Increase or Decrease Area | AA1: Discount/Credit Note (Already applied) | AB1: GST on Credit Note | AC1: Basic Sale Price after discount & Adjustment | AD1: PBIC Rate Carpet Area | AE1: PBIC | AF1: Tax on PBIC | AG1: PBIC on Increase or Decrease Area | AH1: Tax on Diff PBIC | AI1: PBIC after Increase or Decrease Area | AJ1: Tax on PBIC after Increase or Decrease Area | AK1: IFMS Amount | AL1: IFMS Amount after Change Area | AM1: Total BSP & PBIC | AN1: Total GST on BSP/ PBIC | AO1: Total GST+IFMS and Interest | AP1: Grand Total | AQ1: Total Received Till Date | AR1: Interest | AS1: Net Payable with Interest | AT1: ATS Value | AU1: Circle Rate | AV1: Value as per Circle rate | AW1: Stamp Duty Calculation on | AX1: Ceiling up to 1000 of Stamp Duty Calculation Value | AY1: Stamp Duty Percentage | AZ1: stamp duty | BA1: actual stamp duty Ceiling up to Rs. 100 | BB1: Final Total Payable | BC1: Area Variation Super % | BD1: Area Variation Carpet % | BE1: Final Super Area (in sq. mt.) | BF1: Final Carpet Area (in sq. mt.) | BG1: Invocie Date | BH1: Due Date | BI1: Stampduty % for mail merge | BM1: Payment in Favour of | BN1: Account Number | BO1: IFSC Code | BP1: Name of Bank | BQ1: Address of Bank Branch | BR1: Name of Builder | BS1: PAN of the Builder | BT1: Address of the builder | BU1: Address of the Unit/Apartment | BV1: Email ID | BW1: Mobile Number | BX1: Accumulation Amount | BY1: Collection RM | BZ1: Frontend RM
A2: R1 165 | B2: M3M Capital Walk in M3M Capital Phase-1 | C2: WPBOOKING/00001/23-24 | D2: WPFLAP/00016/22-23 | E2: Mr. SHUBHAM SINGH | F2: 45026 | G2: BLOCK-01 | H2: FLOOR 1 | I2: Anchor Units | J2: 649.43 | K2: 649.43 | L2: =K2-J2 -> 0 | M2: 259.95 | N2: 259.95 | O2: =N2-M2 -> 0 | P2: 7500 | Q2: 18737.161 | R2: 22000 | S2: 4870725 | T2: 243536 | U2: =T2/S2 -> 0.049999949 | V2: =L2*P2 -> 0 | W2: =V2*U2 -> 0 | Z2: =S2+V2+X2 -> 4870725 | AC2: =Z2-AA2 -> 4870725 | AD2: =AE2/M2 -> 300 | AE2: 77985 | AF2: 14038 | AG2: =(AD2*O2) -> 0 | AH2: =AG2*18% -> 0 | AI2: =AD2*N2 -> 77985 | AJ2: =ROUNDUP(AI2*18%,0) -> 14038 | AK2: 77985 | AL2: =N2*300 -> 77985 | AM2: =ROUND(AI2+AC2,0) -> 4948710 | AN2: =ROUNDUP(AJ2+W2+T2+Y2-AB2,0) -> 257574 | AO2: =AN2+AL2+AR2 -> 335559 | AP2: =AM2+AO2 -> 5284269 | AQ2: 4653102 | AR2: 0 | AS2: =ROUND(AP2-AQ2,0) -> 631167 | AT2: 0 | AU2: 8800 | AV2: =AU2*N2 -> 2287560 | AW2: =MAX(AM2,AT2,AV2) -> 4948710 | AX2: =CEILING((AW2),1000) -> 4949000 | AY2: 0.07 | AZ2: =AY2*AX2 -> 346430 | BA2: =CEILING(AZ2,100) -> 346500 | BB2: =BA2+AS2 -> 977667 | BC2: =L2/J2% -> 0 | BD2: =O2/M2% -> 0 | BE2: 60.33 | BF2: 24.15 | BG2: 46176 | BH2: =BG2+30 -> 46206 | BI2: 7 | BM2: UBPL M3M CAPITAL MASTER ACCOUNT | BN2: 777705001441 | BO2: ICIC0000399 | BP2: ICICI Bank | BQ2: Shop No - 19, 20, 21, Vipul Orchid Plaza, Suncity, Sector 54, Gurgaon, Haryana -122002 | BR2: Union Buildmart Private Limited | BS2: AABCU4843M | BT2: 41st Floor, Tower-1, M3M International Financial center, sector- 66,Gurugram, Haryana, India 122101 | BU2: (……………..)Village Chauma, Sector – 113, Gurugram, Manesar Urban Complex, GURGAON, HARYANA, INDIA PIN Code: 122017 | BV2: Feedback@m3mindia.com | BW2: 8068970077 | BX2: 0 | BY2: Priya Anand | BZ2: Sabhyata Kapoor
A3: R1 259 | B3: M3M Capital Walk in M3M Capital Phase-1 | C3: WPBOOKING/00009/23-24 | D3: WPFLAP/00005/23-24 | E3: Ms. RACHNA MAHALWALA | F3: 45120 | G3: BLOCK-01 | H3: FLOOR 2 | I3: Anchor Units | J3: 662.58 | K3: 662.58 | L3: =K3-J3 -> 0 | M3: 270.18 | N3: 270.18 | O3: =N3-M3 -> 0 | P3: 7283.0028 | Q3: 17860.582 | R3: 20000 | S3: 4825572 | T3: 241280 | U3: =T3/S3 -> 0.05000029 | V3: =L3*P3 -> 0 | W3: =V3*U3 -> 0 | Z3: =S3+V3+X3 -> 4825572 | AC3: =Z3-AA3 -> 4825572 | AD3: =AE3/M3 -> 300 | AE3: 81054 | AF3: 14590 | AG3: =(AD3*O3) -> 0 | AH3: =AG3*18% -> 0 | AI3: =AD3*N3 -> 81054 | AJ3: =ROUNDUP(AI3*18%,0) -> 14590 | AK3: 81054 | AL3: =N3*300 -> 81054 | AM3: =ROUND(AI3+AC3,0) -> 4906626 | AN3: =ROUNDUP(AJ3+W3+T3+Y3-AB3,0) -> 255870 | AO3: =AN3+AL3+AR3 -> 336924 | AP3: =AM3+AO3 -> 5243550 | AQ3: 3983645 | AR3: 0 | AS3: =ROUND(AP3-AQ3,0) -> 1259905 | AT3: 0 | AU3: 8800 | AV3: =AU3*N3 -> 2377584 | AW3: =MAX(AM3,AT3,AV3) -> 4906626 | AX3: =CEILING((AW3),1000) -> 4907000 | AY3: 0.05 | AZ3: =AY3*AX3 -> 245350 | BA3: =CEILING(AZ3,100) -> 245400 | BB3: =BA3+AS3 -> 1505305 | BC3: =L3/J3% -> 0 | BD3: =O3/M3% -> 0 | BE3: 61.56 | BF3: 25.1 | BG3: 46176 | BH3: =BG3+30 -> 46206 | BI3: 5 | BM3: UBPL M3M CAPITAL MASTER ACCOUNT | BN3: 777705001441 | BO3: ICIC0000399 | BP3: ICICI Bank | BQ3: Shop No - 19, 20, 21, Vipul Orchid Plaza, Suncity, Sector 54, Gurgaon, Haryana -122002 | BR3: Union Buildmart Private Limited | BS3: AABCU4843M | BT3: 41st Floor, Tower-1, M3M International Financial center, sector- 66,Gurugram, Haryana, India 122101 | BU3: (……………..)Village Chauma, Sector – 113, Gurugram, Manesar Urban Complex, GURGAON, HARYANA, INDIA PIN Code: 122017 | BV3: Feedback@m3mindia.com | BW3: 8068970077 | BX3: 0 | BY3: Ritika Singh | BZ3: Sabhyata Kapoor
A4: R2 214 | B4: M3M Capital Walk in M3M Capital Phase-1 | C4: WPBOOKING/00005/24-25 | D4: WPFLAP/00024/23-24 | E4: Ms. Madhulika Nath | F4: 45398 | G4: BLOCK-02 | H4: FLOOR 2 | I4: Retail | J4: 900 | K4: 900 | L4: =K4-J4 -> 0 | M4: 396 | N4: 396 | O4: =N4-M4 -> 0 | P4: 11576.339 | Q4: 26309.861 | R4: 20000 | S4: 10418705 | T4: 520936 | U4: =T4/S4 -> 0.050000072 | V4: =L4*P4 -> 0 | W4: =V4*U4 -> 0 | Z4: =S4+V4+X4 -> 10418705 | AC4: =Z4-AA4 -> 10418705 | AD4: =AE4/M4 -> 300 | AE4: 118800 | AF4: 21384 | AG4: =(AD4*O4) -> 0 | AH4: =AG4*18% -> 0 | AI4: =AD4*N4 -> 118800 | AJ4: =ROUNDUP(AI4*18%,0) -> 21384 | AK4: 118800 | AL4: =N4*300 -> 118800 | AM4: =ROUND(AI4+AC4,0) -> 10537505 | AN4: =ROUNDUP(AJ4+W4+T4+Y4-AB4,0) -> 542320 | AO4: =AN4+AL4+AR4 -> 661120 | AP4: =AM4+AO4 -> 11198625 | AQ4: 9845677.1 | AR4: 0 | AS4: =ROUND(AP4-AQ4,0) -> 1352948 | AT4: 0 | AU4: 8800 | AV4: =AU4*N4 -> 3484800 | AW4: =MAX(AM4,AT4,AV4) -> 10537505 | AX4: =CEILING((AW4),1000) -> 10538000 | AY4: 0.05 | AZ4: =AY4*AX4 -> 526900 | BA4: =CEILING(AZ4,100) -> 526900 | BB4: =BA4+AS4 -> 1879848 | BC4: =L4/J4% -> 0 | BD4: =O4/M4% -> 0 | BE4: 83.61 | BF4: 36.79 | BG4: 46176 | BH4: =BG4+30 -> 46206 | BI4: 5 | BM4: UBPL M3M CAPITAL MASTER ACCOUNT | BN4: 777705001441 | BO4: ICIC0000399 | BP4: ICICI Bank | BQ4: Shop No - 19, 20, 21, Vipul Orchid Plaza, Suncity, Sector 54, Gurgaon, Haryana -122002 | BR4: Union Buildmart Private Limited | BS4: AABCU4843M | BT4: 41st Floor, Tower-1, M3M International Financial center, sector- 66,Gurugram, Haryana, India 122101 | BU4: (……………..)Village Chauma, Sector – 113, Gurugram, Manesar Urban Complex, GURGAON, HARYANA, INDIA PIN Code: 122017 | BV4: Feedback@m3mindia.com | BW4: 8068970077 | BX4: 0 | BY4: Darshan Lal | BZ4: Shubra
A5: R2 215 | B5: M3M Capital Walk in M3M Capital Phase-1 | C5: WPBOOKING/00009/22-23 | D5: WPFLAP/00006/22-23 | E5: Ms. SHASHI | F5: 44897 | G5: BLOCK-02 | H5: FLOOR 2 | I5: Retail | J5: 372.86 | K5: 372.86 | L5: =K5-J5 -> 0 | M5: 158.23 | N5: 158.23 | O5: =N5-M5 -> 0 | P5: 16165 | Q5: 38091.904 | R5: 20000 | S5: 6027282 | T5: 301364 | U5: =T5/S5 -> 0.049999983 | V5: =L5*P5 -> 0 | W5: =V5*U5 -> 0 | Z5: =S5+V5+X5 -> 6027282 | AC5: =Z5-AA5 -> 6027282 | AD5: =AE5/M5 -> 300 | AE5: 47469 | AF5: 8544 | AG5: =(AD5*O5) -> 0 | AH5: =AG5*18% -> 0 | AI5: =AD5*N5 -> 47469 | AJ5: =ROUNDUP(AI5*18%,0) -> 8545 | AK5: 47469 | AL5: =N5*300 -> 47469 | AM5: =ROUND(AI5+AC5,0) -> 6074751 | AN5: =ROUNDUP(AJ5+W5+T5+Y5-AB5,0) -> 309909 | AO5: =AN5+AL5+AR5 -> 357378 | AP5: =AM5+AO5 -> 6432129 | AQ5: 5695781 | AR5: 0 | AS5: =ROUND(AP5-AQ5,0) -> 736348 | AT5: 0 | AU5: 8800 | AV5: =AU5*N5 -> 1392424 | AW5: =MAX(AM5,AT5,AV5) -> 6074751 | AX5: =CEILING((AW5),1000) -> 6075000 | AY5: 0.05 | AZ5: =AY5*AX5 -> 303750 | BA5: =CEILING(AZ5,100) -> 303800 | BB5: =BA5+AS5 -> 1040148 | BC5: =L5/J5% -> 0 | BD5: =O5/M5% -> 0 | BE5: 34.64 | BF5: 14.7 | BG5: 46176 | BH5: =BG5+30 -> 46206 | BI5: 5 | BM5: UBPL M3M CAPITAL MASTER ACCOUNT | BN5: 777705001441 | BO5: ICIC0000399 | BP5: ICICI Bank | BQ5: Shop No - 19, 20, 21, Vipul Orchid Plaza, Suncity, Sector 54, Gurgaon, Haryana -122002 | BR5: Union Buildmart Private Limited | BS5: AABCU4843M | BT5: 41st Floor, Tower-1, M3M International Financial center, sector- 66,Gurugram, Haryana, India 122101 | BU5: (……………..)Village Chauma, Sector – 113, Gurugram, Manesar Urban Complex, GURGAON, HARYANA, INDIA PIN Code: 122017 | BV5: Feedback@m3mindia.com | BW5: 8068970077 | BX5: 0 | BY5: Priya Anand | BZ5: Shubra
A6: R2 LG 22 | B6: M3M Capital Walk in M3M Capital Phase-1 | C6: WPBOOKING/00006/22-23 | D6: WPFLAP/00003/22-23 | E6: Ms. SUMITI KHURANA | F6: 44893 | G6: BLOCK-02 | H6: BASEMENT 2 | I6: Retail | J6: 450.37 | K6: 450.37 | L6: =K6-J6 -> 0 | M6: 193.75 | N6: 193.75 | O6: =N6-M6 -> 0 | P6: 21619 | Q6: 50253.156 | R6: 40000 | S6: 9736549 | T6: 486826 | U6: =T6/S6 -> 0.049999851 | V6: =L6*P6 -> 0 | W6: =V6*U6 -> 0 | Z6: =S6+V6+X6 -> 9736549 | AA6: 1063188 | AB6: 53160 | AC6: =Z6-AA6 -> 8673361 | AD6: =AE6/M6 -> 300 | AE6: 58125 | AF6: 10462 | AG6: =(AD6*O6) -> 0 | AH6: =AG6*18% -> 0 | AI6: =AD6*N6 -> 58125 | AJ6: =ROUNDUP(AI6*18%,0) -> 10463 | AK6: 58125 | AL6: =N6*300 -> 58125 | AM6: =ROUND(AI6+AC6,0) -> 8731486 | AN6: =ROUNDUP(AJ6+W6+T6+Y6-AB6,0) -> 444129 | AO6: =AN6+AL6+AR6 -> 502254 | AP6: =AM6+AO6 -> 9233740 | AQ6: 8084691 | AR6: 0 | AS6: =ROUND(AP6-AQ6,0) -> 1149049 | AT6: 0 | AU6: 8800 | AV6: =AU6*N6 -> 1705000 | AW6: =MAX(AM6,AT6,AV6) -> 8731486 | AX6: =CEILING((AW6),1000) -> 8732000 | AY6: 0.06 | AZ6: =AY6*AX6 -> 523920 | BA6: =CEILING(AZ6,100) -> 524000 | BB6: =BA6+AS6 -> 1673049 | BC6: =L6/J6% -> 0 | BD6: =O6/M6% -> 0 | BE6: 41.84 | BF6: 18 | BG6: 46176 | BH6: =BG6+30 -> 46206 | BI6: 6 | BM6: UBPL M3M CAPITAL MASTER ACCOUNT | BN6: 777705001441 | BO6: ICIC0000399 | BP6: ICICI Bank | BQ6: Shop No - 19, 20, 21, Vipul Orchid Plaza, Suncity, Sector 54, Gurgaon, Haryana -122002 | BR6: Union Buildmart Private Limited | BS6: AABCU4843M | BT6: 41st Floor, Tower-1, M3M International Financial center, sector- 66,Gurugram, Haryana, India 122101 | BU6: (……………..)Village Chauma, Sector – 113, Gurugram, Manesar Urban Complex, GURGAON, HARYANA, INDIA PIN Code: 122017 | BV6: Feedback@m3mindia.com | BW6: 8068970077 | BX6: 0 | BY6: Darshan Lal | BZ6: Shubra
A7: R2 UG 23 | B7: M3M Capital Walk in M3M Capital Phase-1 | C7: WPBOOKING/00013/22-23 | D7: WPFLAP/00009/22-23 | E7: Ms. SHYAMA GOYAL | F7: 44978 | G7: BLOCK-02 | H7: BASEMENT 1 | I7: Retail | J7: 685.67 | K7: 725.28 | L7: =K7-J7 -> 39.61 | M7: 288.8 | N7: 320 | O7: =N7-M7 -> 31.2 | P7: 21094 | Q7: 50081.451 | R7: 28000 | S7: 14463523 | T7: 723178 | U7: =T7/S7 -> 0.050000128 | V7: =L7*R7 -> 1109080 | W7: =V7*U7 -> 55454.142 | Z7: =S7+V7+X7 -> 15572603 | AA7: 899069 | AB7: 44954 | AC7: =Z7-AA7 -> 14673534 | AD7: =AE7/M7 -> 300 | AE7: 86640 | AF7: 15596 | AG7: =(AD7*O7) -> 9360 | AH7: =AG7*18% -> 1684.8 | AI7: =AD7*N7 -> 96000 | AJ7: =ROUNDUP(AI7*18%,0) -> 17280 | AK7: 86640 | AL7: =N7*300 -> 96000 | AM7: =ROUND(AI7+AC7,0) -> 14769534 | AN7: =ROUNDUP(AJ7+W7+T7+Y7-AB7,0) -> 750959 | AO7: =AN7+AL7+AR7 -> 846959 | AP7: =AM7+AO7 -> 15616493 | AQ7: 12724457 | AR7: 0 | AS7: =ROUND(AP7-AQ7,0) -> 2892036 | AT7: 0 | AU7: 8800 | AV7: =AU7*N7 -> 2816000 | AW7: =MAX(AM7,AT7,AV7) -> 14769534 | AX7: =CEILING((AW7),1000) -> 14770000 | AY7: 0.05 | AZ7: =AY7*AX7 -> 738500 | BA7: =CEILING(AZ7,100) -> 738500 | BB7: =BA7+AS7 -> 3630536 | BC7: =L7/J7% -> 5.7768314 | BD7: =O7/M7% -> 10.803324 | BE7: 67.38 | BF7: 29.73 | BG7: 46176 | BH7: =BG7+30 -> 46206 | BI7: 5 | BM7: UBPL M3M CAPITAL MASTER ACCOUNT | BN7: 777705001441 | BO7: ICIC0000399 | BP7: ICICI Bank | BQ7: Shop No - 19, 20, 21, Vipul Orchid Plaza, Suncity, Sector 54, Gurgaon, Haryana -122002 | BR7: Union Buildmart Private Limited | BS7: AABCU4843M | BT7: 41st Floor, Tower-1, M3M International Financial center, sector- 66,Gurugram, Haryana, India 122101 | BU7: (……………..)Village Chauma, Sector – 113, Gurugram, Manesar Urban Complex, GURGAON, HARYANA, INDIA PIN Code: 122017 | BV7: Feedback@m3mindia.com | BW7: 8068970077 | BX7: 0 | BY7: Manish Kumar | BZ7: Shubra
A8: R2 212 | B8: M3M Capital Walk in M3M Capital Phase-1 | C8: WPBOOKING/00014/22-23 | D8: WPFLAP/00010/22-23 | E8: Mr. AJAY KUMAR SHARMA | F8: 44995 | G8: BLOCK-02 | H8: FLOOR 2 | I8: Retail | J8: 1202.34 | K8: 1202.34 | L8: =K8-J8 -> 0 | M8: 535.51 | N8: 535.51 | O8: =N8-M8 -> 0 | P8: 6500 | Q8: 14593.957 | R8: 20000 | S8: 7815210 | T8: 390760 | U8: =T8/S8 -> 0.049999936 | V8: =L8*P8 -> 0 | W8: =V8*U8 -> 0 | Z8: =S8+V8+X8 -> 7815210 | AC8: =Z8-AA8 -> 7815210 | AD8: =AE8/M8 -> 300 | AE8: 160653 | AF8: 28918 | AG8: =(AD8*O8) -> 0 | AH8: =AG8*18% -> 0 | AI8: =AD8*N8 -> 160653 | AJ8: =ROUNDUP(AI8*18%,0) -> 28918 | AK8: 160653 | AL8: =N8*300 -> 160653 | AM8: =ROUND(AI8+AC8,0) -> 7975863 | AN8: =ROUNDUP(AJ8+W8+T8+Y8-AB8,0) -> 419678 | AO8: =AN8+AL8+AR8 -> 580333.48 | AP8: =AM8+AO8 -> 8556196.5 | AQ8: 6975075 | AR8: 2.48 | AS8: =ROUND(AP8-AQ8,0) -> 1581121 | AT8: 0 | AU8: 8800 | AV8: =AU8*N8 -> 4712488 | AW8: =MAX(AM8,AT8,AV8) -> 7975863 | AX8: =CEILING((AW8),1000) -> 7976000 | AY8: 0.06 | AZ8: =AY8*AX8 -> 478560 | BA8: =CEILING(AZ8,100) -> 478600 | BB8: =BA8+AS8 -> 2059721 | BC8: =L8/J8% -> 0 | BD8: =O8/M8% -> 0 | BE8: 111.7 | BF8: 49.75 | BG8: 46176 | BH8: =BG8+30 -> 46206 | BI8: 6 | BM8: UBPL M3M CAPITAL MASTER ACCOUNT | BN8: 777705001441 | BO8: ICIC0000399 | BP8: ICICI Bank | BQ8: Shop No - 19, 20, 21, Vipul Orchid Plaza, Suncity, Sector 54, Gurgaon, Haryana -122002 | BR8: Union Buildmart Private Limited | BS8: AABCU4843M | BT8: 41st Floor, Tower-1, M3M International Financial center, sector- 66,Gurugram, Haryana, India 122101 | BU8: (……………..)Village Chauma, Sector – 113, Gurugram, Manesar Urban Complex, GURGAON, HARYANA, INDIA PIN Code: 122017 | BV8: Feedback@m3mindia.com | BW8: 8068970077 | BX8: 0 | BY8: Vidhi Singh | BZ8: Shubra
A9: R2 115 | B9: M3M Capital Walk in M3M Capital Phase-1 | C9: WPBOOKING/00003/22-23 | D9: WPFLAP/00002/22-23 | E9: Mr. SATYA VRAT | F9: 44868 | G9: BLOCK-02 | H9: FLOOR 1 | I9: Retail | J9: 372.86 | K9: 372.86 | L9: =K9-J9 -> 0 | M9: 158.23 | N9: 158.23 | O9: =N9-M9 -> 0 | P9: 15782.999 | Q9: 37191.74 | R9: 22000 | S9: 5884849 | T9: 294242 | U9: =T9/S9 -> 0.049999924 | V9: =L9*P9 -> 0 | W9: =V9*U9 -> 0 | Z9: =S9+V9+X9 -> 5884849 | AA9: 728980 | AB9: 36450 | AC9: =Z9-AA9 -> 5155869 | AD9: =AE9/M9 -> 300 | AE9: 47469 | AF9: 8544 | AG9: =(AD9*O9) -> 0 | AH9: =AG9*18% -> 0 | AI9: =AD9*N9 -> 47469 | AJ9: =ROUNDUP(AI9*18%,0) -> 8545 | AK9: 47469 | AL9: =N9*300 -> 47469 | AM9: =ROUND(AI9+AC9,0) -> 5203338 | AN9: =ROUNDUP(AJ9+W9+T9+Y9-AB9,0) -> 266337 | AO9: =AN9+AL9+AR9 -> 313806 | AP9: =AM9+AO9 -> 5517144 | AQ9: 4795753 | AR9: 0 | AS9: =ROUND(AP9-AQ9,0) -> 721391 | AT9: 0 | AU9: 8800 | AV9: =AU9*N9 -> 1392424 | AW9: =MAX(AM9,AT9,AV9) -> 5203338 | AX9: =CEILING((AW9),1000) -> 5204000 | AY9: 0.06 | AZ9: =AY9*AX9 -> 312240 | BA9: =CEILING(AZ9,100) -> 312300 | BB9: =BA9+AS9 -> 1033691 | BC9: =L9/J9% -> 0 | BD9: =O9/M9% -> 0 | BE9: 34.64 | BF9: 14.7 | BG9: 46176 | BH9: =BG9+30 -> 46206 | BI9: 6 | BM9: UBPL M3M CAPITAL MASTER ACCOUNT | BN9: 777705001441 | BO9: ICIC0000399 | BP9: ICICI Bank | BQ9: Shop No - 19, 20, 21, Vipul Orchid Plaza, Suncity, Sector 54, Gurgaon, Haryana -122002 | BR9: Union Buildmart Private Limited | BS9: AABCU4843M | BT9: 41st Floor, Tower-1, M3M International Financial center, sector- 66,Gurugram, Haryana, India 122101 | BU9: (……………..)Village Chauma, Sector – 113, Gurugram, Manesar Urban Complex, GURGAON, HARYANA, INDIA PIN Code: 122017 | BV9: Feedback@m3mindia.com | BW9: 8068970077 | BX9: 0 | BY9: Priya Anand | BZ9: Shubra
A10: R2 112A | B10: M3M Capital Walk in M3M Capital Phase-1 | C10: WPBOOKING/00017/22-23 | D10: WPFLAP/00012/22-23 | E10: Ms. SAVITA TANWAR | F10: 45001 | G10: BLOCK-02 | H10: FLOOR 1 | I10: Retail | J10: 761.88 | K10: 780 | L10: =K10-J10 -> 18.12 | M10: 330.45 | N10: 348 | O10: =N10-M10 -> 17.55 | P10: 12377.222 | Q10: 28536.717 | R10: 22000 | S10: 9429958 | T10: 471500 | U10: =T10/S10 -> 0.050000223 | V10: =L10*R10 -> 398640 | W10: =V10*U10 -> 19932.089 | Z10: =S10+V10+X10 -> 9828598 | AC10: =Z10-AA10 -> 9828598 | AD10: =AE10/M10 -> 300 | AE10: 99135 | AF10: 17844 | AG10: =(AD10*O10) -> 5265 | AH10: =AG10*18% -> 947.7 | AI10: =AD10*N10 -> 104400 | AJ10: =ROUNDUP(AI10*18%,0) -> 18792 | AK10: 99135 | AL10: =N10*300 -> 104400 | AM10: =ROUND(AI10+AC10,0) -> 9932998 | AN10: =ROUNDUP(AJ10+W10+T10+Y10-AB10,0) -> 510225 | AO10: =AN10+AL10+AR10 -> 614627.1 | AP10: =AM10+AO10 -> 10547625 | AQ10: 8882188.4 | AR10: 2.1 | AS10: =ROUND(AP10-AQ10,0) -> 1665437 | AT10: 0 | AU10: 8800 | AV10: =AU10*N10 -> 3062400 | AW10: =MAX(AM10,AT10,AV10) -> 9932998 | AX10: =CEILING((AW10),1000) -> 9933000 | AY10: 0.05 | AZ10: =AY10*AX10 -> 496650 | BA10: =CEILING(AZ10,100) -> 496700 | BB10: =BA10+AS10 -> 2162137 | BC10: =L10/J10% -> 2.3783273 | BD10: =O10/M10% -> 5.3109396 | BE10: 72.46 | BF10: 32.33 | BG10: 46176 | BH10: =BG10+30 -> 46206 | BI10: 5 | BM10: UBPL M3M CAPITAL MASTER ACCOUNT | BN10: 777705001441 | BO10: ICIC0000399 | BP10: ICICI Bank | BQ10: Shop No - 19, 20, 21, Vipul Orchid Plaza, Suncity, Sector 54, Gurgaon, Haryana -122002 | BR10: Union Buildmart Private Limited | BS10: AABCU4843M | BT10: 41st Floor, Tower-1, M3M International Financial center, sector- 66,Gurugram, Haryana, India 122101 | BU10: (……………..)Village Chauma, Sector – 113, Gurugram, Manesar Urban Complex, GURGAON, HARYANA, INDIA PIN Code: 122017 | BV10: Feedback@m3mindia.com | BW10: 8068970077 | BX10: 0 | BY10: Manish Kumar | BZ10: Shubra
A11: R1 162 | B11: M3M Capital Walk in M3M Capital Phase-1 | C11: WPBOOKING/00004/24-25 | D11: WPFLAP/00025/23-24 | E11: Mr. Ram Niwas Gupta | F11: 45383 | G11: BLOCK-01 | H11: FLOOR 1 | I11: Anchor Units | J11: 662.58 | K11: 662.58 | L11: =K11-J11 -> 0 | M11: 270.18 | N11: 270.18 | O11: =N11-M11 -> 0 | P11: 14400.002 | Q11: 35314.061 | R11: 22000 | S11: 9541153 | T11: 477058 | U11: =T11/S11 -> 0.050000037 | V11: =L11*P11 -> 0 | W11: =V11*U11 -> 0 | Z11: =S11+V11+X11 -> 9541153 | AC11: =Z11-AA11 -> 9541153 | AD11: =AE11/M11 -> 300 | AE11: 81054 | AF11: 14590 | AG11: =(AD11*O11) -> 0 | AH11: =AG11*18% -> 0 | AI11: =AD11*N11 -> 81054 | AJ11: =ROUNDUP(AI11*18%,0) -> 14590 | AK11: 81054 | AL11: =N11*300 -> 81054 | AM11: =ROUND(AI11+AC11,0) -> 9622207 | AN11: =ROUNDUP(AJ11+W11+T11+Y11-AB11,0) -> 491648 | AO11: =AN11+AL11+AR11 -> 572981.66 | AP11: =AM11+AO11 -> 10195189 | AQ11: 8956359.6 | AR11: 279.66 | AS11: =ROUND(AP11-AQ11,0) -> 1238829 | AT11: 0 | AU11: 8800 | AV11: =AU11*N11 -> 2377584 | AW11: =MAX(AM11,AT11,AV11) -> 9622207 | AX11: =CEILING((AW11),1000) -> 9623000 | AY11: 0.07 | AZ11: =AY11*AX11 -> 673610 | BA11: =CEILING(AZ11,100) -> 673700 | BB11: =BA11+AS11 -> 1912529 | BC11: =L11/J11% -> 0 | BD11: =O11/M11% -> 0 | BE11: 61.56 | BF11: 25.1 | BG11: 46176 | BH11: =BG11+30 -> 46206 | BI11: 7 | BM11: UBPL M3M CAPITAL MASTER ACCOUNT | BN11: 777705001441 | BO11: ICIC0000399 | BP11: ICICI Bank | BQ11: Shop No - 19, 20, 21, Vipul Orchid Plaza, Suncity, Sector 54, Gurgaon, Haryana -122002 | BR11: Union Buildmart Private Limited | BS11: AABCU4843M | BT11: 41st Floor, Tower-1, M3M International Financial center, sector- 66,Gurugram, Haryana, India 122101 | BU11: (……………..)Village Chauma, Sector – 113, Gurugram, Manesar Urban Complex, GURGAON, HARYANA, INDIA PIN Code: 122017 | BV11: Feedback@m3mindia.com | BW11: 8068970077 | BX11: 0 | BY11: Ritika Singh | BZ11: Sabhyata Kapoor
A12: R2 216 | B12: M3M Capital Walk in M3M Capital Phase-1 | C12: WPBOOKING/00011/22-23 | D12: WPFLAP/00007/22-23 | E12: Ms. Runa Singh | F12: 44958 | G12: BLOCK-02 | H12: FLOOR 2 | I12: Retail | J12: 684.59 | K12: 725 | L12: =K12-J12 -> 40.41 | M12: 288.48 | N12: 319 | O12: =N12-M12 -> 30.52 | P12: 12349.999 | Q12: 29307.702 | R12: 20000 | S12: 8454686 | T12: 422736 | U12: =T12/S12 -> 0.050000201 | V12: =L12*R12 -> 808200 | W12: =V12*U12 -> 40410.163 | Z12: =S12+V12+X12 -> 9262886 | AC12: =Z12-AA12 -> 9262886 | AD12: =AE12/M12 -> 300 | AE12: 86544 | AF12: 15578 | AG12: =(AD12*O12) -> 9156 | AH12: =AG12*18% -> 1648.08 | AI12: =AD12*N12 -> 95700 | AJ12: =ROUNDUP(AI12*18%,0) -> 17226 | AK12: 86544 | AL12: =N12*300 -> 95700 | AM12: =ROUND(AI12+AC12,0) -> 9358586 | AN12: =ROUNDUP(AJ12+W12+T12+Y12-AB12,0) -> 480373 | AO12: =AN12+AL12+AR12 -> 576444.86 | AP12: =AM12+AO12 -> 9935030.9 | AQ12: 7909741 | AR12: 371.86 | AS12: =ROUND(AP12-AQ12,0) -> 2025290 | AT12: 9584260 | AU12: 8800 | AV12: =AU12*N12 -> 2807200 | AW12: =MAX(AM12,AT12,AV12) -> 9584260 | AX12: =CEILING((AW12),1000) -> 9585000 | AY12: 0.05 | AZ12: =AY12*AX12 -> 479250 | BA12: =CEILING(AZ12,100) -> 479300 | BB12: =BA12+AS12 -> 2504590 | BC12: =L12/J12% -> 5.9028031 | BD12: =O12/M12% -> 10.57959 | BE12: 67.35 | BF12: 29.64 | BG12: 46176 | BH12: =BG12+30 -> 46206 | BI12: 5 | BM12: UBPL M3M CAPITAL MASTER ACCOUNT | BN12: 777705001441 | BO12: ICIC0000399 | BP12: ICICI Bank | BQ12: Shop No - 19, 20, 21, Vipul Orchid Plaza, Suncity, Sector 54, Gurgaon, Haryana -122002 | BR12: Union Buildmart Private Limited | BS12: AABCU4843M | BT12: 41st Floor, Tower-1, M3M International Financial center, sector- 66,Gurugram, Haryana, India 122101 | BU12: (……………..)Village Chauma, Sector – 113, Gurugram, Manesar Urban Complex, GURGAON, HARYANA, INDIA PIN Code: 122017 | BV12: Feedback@m3mindia.com | BW12: 8068970077 | BX12: 0 | BY12: Manish Kumar | BZ12: Shubra
A13: R2 UG 19 | B13: M3M Capital Walk in M3M Capital Phase-1 | C13: WPBOOKING/00004/23-24 | D13: WPFLAP/00003/23-24 | E13: Ms. KAVYA RAI | F13: 45055 | G13: BLOCK-02 | H13: BASEMENT 1 | I13: Retail | J13: 1204.49 | K13: 1204.49 | L13: =K13-J13 -> 0 | M13: 537.55 | N13: 552 | O13: =N13-M13 -> 14.45 | P13: 9000 | Q13: 20166.329 | R13: 28000 | S13: 10840410 | T13: 542022 | U13: =T13/S13 -> 0.050000138 | V13: =L13*P13 -> 0 | W13: =V13*U13 -> 0 | Z13: =S13+V13+X13 -> 10840410 | AA13: 96841 | AB13: 4842 | AC13: =Z13-AA13 -> 10743569 | AD13: =AE13/M13 -> 300 | AE13: 161265 | AF13: 29028 | AG13: =(AD13*O13) -> 4335 | AH13: =AG13*18% -> 780.3 | AI13: =AD13*N13 -> 165600 | AJ13: =ROUNDUP(AI13*18%,0) -> 29808 | AK13: 161265 | AL13: =N13*300 -> 165600 | AM13: =ROUND(AI13+AC13,0) -> 10909169 | AN13: =ROUNDUP(AJ13+W13+T13+Y13-AB13,0) -> 566988 | AO13: =AN13+AL13+AR13 -> 733043 | AP13: =AM13+AO13 -> 11642212 | AQ13: 10044942 | AR13: 455 | AS13: =ROUND(AP13-AQ13,0) -> 1597270 | AT13: 0 | AU13: 8800 | AV13: =AU13*N13 -> 4857600 | AW13: =MAX(AM13,AT13,AV13) -> 10909169 | AX13: =CEILING((AW13),1000) -> 10910000 | AY13: 0.05 | AZ13: =AY13*AX13 -> 545500 | BA13: =CEILING(AZ13,100) -> 545500 | BB13: =BA13+AS13 -> 2142770 | BC13: =L13/J13% -> 0 | BD13: =O13/M13% -> 2.688122 | BE13: 111.9 | BF13: 51.28 | BG13: 46176 | BH13: =BG13+30 -> 46206 | BI13: 5 | BM13: UBPL M3M CAPITAL MASTER ACCOUNT | BN13: 777705001441 | BO13: ICIC0000399 | BP13: ICICI Bank | BQ13: Shop No - 19, 20, 21, Vipul Orchid Plaza, Suncity, Sector 54, Gurgaon, Haryana -122002 | BR13: Union Buildmart Private Limited | BS13: AABCU4843M | BT13: 41st Floor, Tower-1, M3M International Financial center, sector- 66,Gurugram, Haryana, India 122101 | BU13: (……………..)Village Chauma, Sector – 113, Gurugram, Manesar Urban Complex, GURGAON, HARYANA, INDIA PIN Code: 122017 | BV13: Feedback@m3mindia.com | BW13: 8068970077 | BX13: 0 | BY13: Manish Kumar | BZ13: Shubra
A14: R2 217 | B14: M3M Capital Walk in M3M Capital Phase-1 | C14: WPBOOKING/00019/22-23 | D14: WPFLAP/00014/22-23 | E14: Mr. MANMEET VINOD SEHGAL | F14: 45008 | G14: BLOCK-02 | H14: FLOOR 2 | I14: Retail | J14: 1194.8 | K14: 1194.8 | L14: =K14-J14 -> 0 | M14: 529.59 | N14: 529.59 | O14: =N14-M14 -> 0 | P14: 10063 | Q14: 22702.982 | R14: 20000 | S14: 12023272 | T14: 601164 | U14: =T14/S14 -> 0.050000033 | V14: =L14*P14 -> 0 | W14: =V14*U14 -> 0 | Z14: =S14+V14+X14 -> 12023272 | AC14: =Z14-AA14 -> 12023272 | AD14: =AE14/M14 -> 300 | AE14: 158877 | AF14: 28598 | AG14: =(AD14*O14) -> 0 | AH14: =AG14*18% -> 0 | AI14: =AD14*N14 -> 158877 | AJ14: =ROUNDUP(AI14*18%,0) -> 28598 | AK14: 158877 | AL14: =N14*300 -> 158877 | AM14: =ROUND(AI14+AC14,0) -> 12182149 | AN14: =ROUNDUP(AJ14+W14+T14+Y14-AB14,0) -> 629762 | AO14: =AN14+AL14+AR14 -> 789148.16 | AP14: =AM14+AO14 -> 12971297 | AQ14: 11285496 | AR14: 509.16 | AS14: =ROUND(AP14-AQ14,0) -> 1685801 | AT14: 0 | AU14: 8800 | AV14: =AU14*N14 -> 4660392 | AW14: =MAX(AM14,AT14,AV14) -> 12182149 | AX14: =CEILING((AW14),1000) -> 12183000 | AY14: 0.06 | AZ14: =AY14*AX14 -> 730980 | BA14: =CEILING(AZ14,100) -> 731000 | BB14: =BA14+AS14 -> 2416801 | BC14: =L14/J14% -> 0 | BD14: =O14/M14% -> 0 | BE14: 111 | BF14: 49.2 | BG14: 46176 | BH14: =BG14+30 -> 46206 | BI14: 6 | BM14: UBPL M3M CAPITAL MASTER ACCOUNT | BN14: 777705001441 | BO14: ICIC0000399 | BP14: ICICI Bank | BQ14: Shop No - 19, 20, 21, Vipul Orchid Plaza, Suncity, Sector 54, Gurgaon, Haryana -122002 | BR14: Union Buildmart Private Limited | BS14: AABCU4843M | BT14: 41st Floor, Tower-1, M3M International Financial center, sector- 66,Gurugram, Haryana, India 122101 | BU14: (……………..)Village Chauma, Sector – 113, Gurugram, Manesar Urban Complex, GURGAON, HARYANA, INDIA PIN Code: 122017 | BV14: Feedback@m3mindia.com | BW14: 8068970077 | BX14: 0 | BY14: Darshan Lal | BZ14: Shubra
A15: R2 LG 23 | B15: M3M Capital Walk in M3M Capital Phase-1 | C15: WPBOOKING/00014/23-24 | D15: WPFLAP/00020/23-24 | E15: Mr. Balraj Singh | F15: 45239 | G15: BLOCK-02 | H15: BASEMENT 2 | I15: Retail | J15: 618.93 | K15: 618.93 | L15: =K15-J15 -> 0 | M15: 273.94 | N15: 273.94 | O15: =N15-M15 -> 0 | P15: 31676.999 | Q15: 71569.851 | R15: 40000 | S15: 19605845 | T15: 980292 | U15: =T15/S15 -> 0.049999987 | V15: =L15*P15 -> 0 | W15: =V15*U15 -> 0 | Z15: =S15+V15+X15 -> 19605845 | AC15: =Z15-AA15 -> 19605845 | AD15: =AE15/M15 -> 300 | AE15: 82182 | AF15: 14792 | AG15: =(AD15*O15) -> 0 | AH15: =AG15*18% -> 0 | AI15: =AD15*N15 -> 82182 | AJ15: =ROUNDUP(AI15*18%,0) -> 14793 | AK15: 82182 | AL15: =N15*300 -> 82182 | AM15: =ROUND(AI15+AC15,0) -> 19688027 | AN15: =ROUNDUP(AJ15+W15+T15+Y15-AB15,0) -> 995085 | AO15: =AN15+AL15+AR15 -> 1077887 | AP15: =AM15+AO15 -> 20765914 | AQ15: 20452956 | AR15: 620 | AS15: =ROUND(AP15-AQ15,0) -> 312958 | AT15: 0 | AU15: 8800 | AV15: =AU15*N15 -> 2410672 | AW15: =MAX(AM15,AT15,AV15) -> 19688027 | AX15: =CEILING((AW15),1000) -> 19689000 | AY15: 0.07 | AZ15: =AY15*AX15 -> 1378230 | BA15: =CEILING(AZ15,100) -> 1378300 | BB15: =BA15+AS15 -> 1691258 | BC15: =L15/J15% -> 0 | BD15: =O15/M15% -> 0 | BE15: 57.5 | BF15: 25.45 | BG15: 46176 | BH15: =BG15+30 -> 46206 | BI15: 7 | BM15: UBPL M3M CAPITAL MASTER ACCOUNT | BN15: 777705001441 | BO15: ICIC0000399 | BP15: ICICI Bank | BQ15: Shop No - 19, 20, 21, Vipul Orchid Plaza, Suncity, Sector 54, Gurgaon, Haryana -122002 | BR15: Union Buildmart Private Limited | BS15: AABCU4843M | BT15: 41st Floor, Tower-1, M3M International Financial center, sector- 66,Gurugram, Haryana, India 122101 | BU15: (……………..)Village Chauma, Sector – 113, Gurugram, Manesar Urban Complex, GURGAON, HARYANA, INDIA PIN Code: 122017 | BV15: Feedback@m3mindia.com | BW15: 8068970077 | BX15: 0 | BY15: Chandrima | BZ15: Shubra
A16: R1 260 | B16: M3M Capital Walk in M3M Capital Phase-1 | C16: WPBOOKING/00006/23-24 | D16: WPFLAP/00017/22-23 | E16: Ms. SHIKHA WARIKOO | F16: 45089 | G16: BLOCK-01 | H16: FLOOR 2 | I16: Anchor Units | J16: 662.58 | K16: 662.58 | L16: =K16-J16 -> 0 | M16: 270.18 | N16: 270.18 | O16: =N16-M16 -> 0 | P16: 6925.7282 | Q16: 16984.414 | R16: 20000 | S16: 4588849 | T16: 229444 | U16: =T16/S16 -> 0.050000338 | V16: =L16*P16 -> 0 | W16: =V16*U16 -> 0 | Z16: =S16+V16+X16 -> 4588849 | AC16: =Z16-AA16 -> 4588849 | AD16: =AE16/M16 -> 300 | AE16: 81054 | AF16: 14590 | AG16: =(AD16*O16) -> 0 | AH16: =AG16*18% -> 0 | AI16: =AD16*N16 -> 81054 | AJ16: =ROUNDUP(AI16*18%,0) -> 14590 | AK16: 81054 | AL16: =N16*300 -> 81054 | AM16: =ROUND(AI16+AC16,0) -> 4669903 | AN16: =ROUNDUP(AJ16+W16+T16+Y16-AB16,0) -> 244034 | AO16: =AN16+AL16+AR16 -> 325768 | AP16: =AM16+AO16 -> 4995671 | AQ16: 3819866 | AR16: 680 | AS16: =ROUND(AP16-AQ16,0) -> 1175805 | AT16: 0 | AU16: 8800 | AV16: =AU16*N16 -> 2377584 | AW16: =MAX(AM16,AT16,AV16) -> 4669903 | AX16: =CEILING((AW16),1000) -> 4670000 | AY16: 0.05 | AZ16: =AY16*AX16 -> 233500 | BA16: =CEILING(AZ16,100) -> 233500 | BB16: =BA16+AS16 -> 1409305 | BC16: =L16/J16% -> 0 | BD16: =O16/M16% -> 0 | BE16: 61.56 | BF16: 25.1 | BG16: 46176 | BH16: =BG16+30 -> 46206 | BI16: 5 | BM16: UBPL M3M CAPITAL MASTER ACCOUNT | BN16: 777705001441 | BO16: ICIC0000399 | BP16: ICICI Bank | BQ16: Shop No - 19, 20, 21, Vipul Orchid Plaza, Suncity, Sector 54, Gurgaon, Haryana -122002 | BR16: Union Buildmart Private Limited | BS16: AABCU4843M | BT16: 41st Floor, Tower-1, M3M International Financial center, sector- 66,Gurugram, Haryana, India 122101 | BU16: (……………..)Village Chauma, Sector – 113, Gurugram, Manesar Urban Complex, GURGAON, HARYANA, INDIA PIN Code: 122017 | BV16: Feedback@m3mindia.com | BW16: 8068970077 | BX16: 0 | BY16: Ritika Singh | BZ16: Sabhyata Kapoor
A17: R2 212a | B17: M3M Capital Walk in M3M Capital Phase-1 | C17: WPBOOKING/00012/22-23 | D17: WPFLAP/00008/22-23 | E17: Mr. RAVI MADAAN | F17: 44967 | G17: BLOCK-02 | H17: FLOOR 2 | I17: Retail | J17: 761.88 | K17: 780 | L17: =K17-J17 -> 18.12 | M17: 330.45 | N17: 348 | O17: =N17-M17 -> 17.55 | P17: 10600 | Q17: 24439.183 | R17: 20000 | S17: 8075928 | T17: 403798 | U17: =T17/S17 -> 0.050000198 | V17: =L17*R17 -> 362400 | W17: =V17*U17 -> 18120.072 | Z17: =S17+V17+X17 -> 8438328 | AC17: =Z17-AA17 -> 8438328 | AD17: =AE17/M17 -> 300 | AE17: 99135 | AF17: 17844 | AG17: =(AD17*O17) -> 5265 | AH17: =AG17*18% -> 947.7 | AI17: =AD17*N17 -> 104400 | AJ17: =ROUNDUP(AI17*18%,0) -> 18792 | AK17: 99135 | AL17: =N17*300 -> 104400 | AM17: =ROUND(AI17+AC17,0) -> 8542728 | AN17: =ROUNDUP(AJ17+W17+T17+Y17-AB17,0) -> 440711 | AO17: =AN17+AL17+AR17 -> 548282.26 | AP17: =AM17+AO17 -> 9091010.3 | AQ17: 7591331.7 | AR17: 3171.26 | AS17: =ROUND(AP17-AQ17,0) -> 1499679 | AT17: 0 | AU17: 8800 | AV17: =AU17*N17 -> 3062400 | AW17: =MAX(AM17,AT17,AV17) -> 8542728 | AX17: =CEILING((AW17),1000) -> 8543000 | AY17: 0.07 | AZ17: =AY17*AX17 -> 598010 | BA17: =CEILING(AZ17,100) -> 598100 | BB17: =BA17+AS17 -> 2097779 | BC17: =L17/J17% -> 2.3783273 | BD17: =O17/M17% -> 5.3109396 | BE17: 72.46 | BF17: 32.33 | BG17: 46176 | BH17: =BG17+30 -> 46206 | BI17: 7 | BM17: UBPL M3M CAPITAL MASTER ACCOUNT | BN17: 777705001441 | BO17: ICIC0000399 | BP17: ICICI Bank | BQ17: Shop No - 19, 20, 21, Vipul Orchid Plaza, Suncity, Sector 54, Gurgaon, Haryana -122002 | BR17: Union Buildmart Private Limited | BS17: AABCU4843M | BT17: 41st Floor, Tower-1, M3M International Financial center, sector- 66,Gurugram, Haryana, India 122101 | BU17: (……………..)Village Chauma, Sector – 113, Gurugram, Manesar Urban Complex, GURGAON, HARYANA, INDIA PIN Code: 122017 | BV17: Feedback@m3mindia.com | BW17: 8068970077 | BX17: 0 | BY17: Manish Kumar | BZ17: Shubra
A18: R2 116 | B18: M3M Capital Walk in M3M Capital Phase-1 | C18: WPBOOKING/00018/22-23 | D18: WPFLAP/00013/22-23 | E18: Mr. HEMANT AGGARWAL | F18: 45005 | G18: BLOCK-02 | H18: FLOOR 1 | I18: Retail | J18: 684.59 | K18: 725 | L18: =K18-J18 -> 40.41 | M18: 288.48 | N18: 319 | O18: =N18-M18 -> 30.52 | P18: 12598.91 | Q18: 29898.392 | R18: 22000 | S18: 8625088 | T18: 431256 | U18: =T18/S18 -> 0.050000186 | V18: =L18*R18 -> 889020 | W18: =V18*U18 -> 44451.165 | Z18: =S18+V18+X18 -> 9514108 | AC18: =Z18-AA18 -> 9514108 | AD18: =AE18/M18 -> 300 | AE18: 86544 | AF18: 15578 | AG18: =(AD18*O18) -> 9156 | AH18: =AG18*18% -> 1648.08 | AI18: =AD18*N18 -> 95700 | AJ18: =ROUNDUP(AI18*18%,0) -> 17226 | AK18: 86544 | AL18: =N18*300 -> 95700 | AM18: =ROUND(AI18+AC18,0) -> 9609808 | AN18: =ROUNDUP(AJ18+W18+T18+Y18-AB18,0) -> 492934 | AO18: =AN18+AL18+AR18 -> 593917 | AP18: =AM18+AO18 -> 10203725 | AQ18: 8150709.8 | AR18: 5283 | AS18: =ROUND(AP18-AQ18,0) -> 2053015 | AT18: 0 | AU18: 8800 | AV18: =AU18*N18 -> 2807200 | AW18: =MAX(AM18,AT18,AV18) -> 9609808 | AX18: =CEILING((AW18),1000) -> 9610000 | AY18: 0.07 | AZ18: =AY18*AX18 -> 672700 | BA18: =CEILING(AZ18,100) -> 672700 | BB18: =BA18+AS18 -> 2725715 | BC18: =L18/J18% -> 5.9028031 | BD18: =O18/M18% -> 10.57959 | BE18: 67.35 | BF18: 29.64 | BG18: 46176 | BH18: =BG18+30 -> 46206 | BI18: 7 | BM18: UBPL M3M CAPITAL MASTER ACCOUNT | BN18: 777705001441 | BO18: ICIC0000399 | BP18: ICICI Bank | BQ18: Shop No - 19, 20, 21, Vipul Orchid Plaza, Suncity, Sector 54, Gurgaon, Haryana -122002 | BR18: Union Buildmart Private Limited | BS18: AABCU4843M | BT18: 41st Floor, Tower-1, M3M International Financial center, sector- 66,Gurugram, Haryana, India 122101 | BU18: (……………..)Village Chauma, Sector – 113, Gurugram, Manesar Urban Complex, GURGAON, HARYANA, INDIA PIN Code: 122017 | BV18: Feedback@m3mindia.com | BW18: 8068970077 | BX18: 0 | BY18: Ritika Singh | BZ18: Shubra
A19: R2 UG 22 | B19: M3M Capital Walk in M3M Capital Phase-1 | C19: WPBOOKING/00001/22-23 | D19: CW1FLAP/00001/22-23 | E19: Ms. SARLA ARYA | F19: 44861 | G19: BLOCK-02 | H19: BASEMENT 1 | I19: Retail | J19: 380.18 | K19: 380.18 | L19: =K19-J19 -> 0 | M19: 160.17 | N19: 160.17 | O19: =N19-M19 -> 0 | P19: 14550 | Q19: 34535.924 | R19: 28000 | S19: 5531619 | T19: 276580 | U19: =T19/S19 -> 0.049999828 | V19: =L19*P19 -> 0 | W19: =V19*U19 -> 0 | Z19: =S19+V19+X19 -> 5531619 | AA19: 1936066 | AB19: 96804 | AC19: =Z19-AA19 -> 3595553 | AD19: =AE19/M19 -> 300 | AE19: 48051 | AF19: 8650 | AG19: =(AD19*O19) -> 0 | AH19: =AG19*18% -> 0 | AI19: =AD19*N19 -> 48051 | AJ19: =ROUNDUP(AI19*18%,0) -> 8650 | AK19: 48051 | AL19: =N19*300 -> 48051 | AM19: =ROUND(AI19+AC19,0) -> 3643604 | AN19: =ROUNDUP(AJ19+W19+T19+Y19-AB19,0) -> 188426 | AO19: =AN19+AL19+AR19 -> 237124 | AP19: =AM19+AO19 -> 3880728 | AQ19: 3055784 | AR19: 647 | AS19: =ROUND(AP19-AQ19,0) -> 824944 | AT19: 0 | AU19: 8800 | AV19: =AU19*N19 -> 1409496 | AW19: =MAX(AM19,AT19,AV19) -> 3643604 | AX19: =CEILING((AW19),1000) -> 3644000 | AY19: 0.05 | AZ19: =AY19*AX19 -> 182200 | BA19: =CEILING(AZ19,100) -> 182200 | BB19: =BA19+AS19 -> 1007144 | BC19: =L19/J19% -> 0 | BD19: =O19/M19% -> 0 | BE19: 35.32 | BF19: 14.88 | BG19: 46176 | BH19: =BG19+30 -> 46206 | BI19: 5 | BM19: UBPL M3M CAPITAL MASTER ACCOUNT | BN19: 777705001441 | BO19: ICIC0000399 | BP19: ICICI Bank | BQ19: Shop No - 19, 20, 21, Vipul Orchid Plaza, Suncity, Sector 54, Gurgaon, Haryana -122002 | BR19: Union Buildmart Private Limited | BS19: AABCU4843M | BT19: 41st Floor, Tower-1, M3M International Financial center, sector- 66,Gurugram, Haryana, India 122101 | BU19: (……………..)Village Chauma, Sector – 113, Gurugram, Manesar Urban Complex, GURGAON, HARYANA, INDIA PIN Code: 122017 | BV19: Feedback@m3mindia.com | BW19: 8068970077 | BX19: 0 | BY19: Preeti Chauhan | BZ19: Shubra
A20: R1 147 | B20: M3M Capital Walk in M3M Capital Phase-1 | C20: WPBOOKING/00002/23-24 | D20: WPFLAP/00018/22-23 | E20: Mr. VIKRAM RAJ JAISWAL | F20: 45040 | G20: BLOCK-01 | H20: FLOOR 1 | I20: Anchor Units | J20: 391.09 | K20: 391.09 | L20: =K20-J20 -> 0 | M20: 156.08 | N20: 156.08 | O20: =N20-M20 -> 0 | P20: 22000 | Q20: 55125.448 | R20: 22000 | S20: 8603980 | T20: 430200 | U20: =T20/S20 -> 0.050000116 | V20: =L20*P20 -> 0 | W20: =V20*U20 -> 0 | Z20: =S20+V20+X20 -> 8603980 | AC20: =Z20-AA20 -> 8603980 | AD20: =AE20/M20 -> 300 | AE20: 46824 | AF20: 8428 | AG20: =(AD20*O20) -> 0 | AH20: =AG20*18% -> 0 | AI20: =AD20*N20 -> 46824 | AJ20: =ROUNDUP(AI20*18%,0) -> 8429 | AK20: 46824 | AL20: =N20*300 -> 46824 | AM20: =ROUND(AI20+AC20,0) -> 8650804 | AN20: =ROUNDUP(AJ20+W20+T20+Y20-AB20,0) -> 438629 | AO20: =AN20+AL20+AR20 -> 505543 | AP20: =AM20+AO20 -> 9156347 | AQ20: 3820187 | AR20: 20090 | AS20: =ROUND(AP20-AQ20,0) -> 5336160 | AT20: 0 | AU20: 8800 | AV20: =AU20*N20 -> 1373504 | AW20: =MAX(AM20,AT20,AV20) -> 8650804 | AX20: =CEILING((AW20),1000) -> 8651000 | AY20: 0.07 | AZ20: =AY20*AX20 -> 605570 | BA20: =CEILING(AZ20,100) -> 605600 | BB20: =BA20+AS20 -> 5941760 | BC20: =L20/J20% -> 0 | BD20: =O20/M20% -> 0 | BE20: 36.33 | BF20: 14.5 | BG20: 46176 | BH20: =BG20+30 -> 46206 | BI20: 7 | BM20: UBPL M3M CAPITAL MASTER ACCOUNT | BN20: 777705001441 | BO20: ICIC0000399 | BP20: ICICI Bank | BQ20: Shop No - 19, 20, 21, Vipul Orchid Plaza, Suncity, Sector 54, Gurgaon, Haryana -122002 | BR20: Union Buildmart Private Limited | BS20: AABCU4843M | BT20: 41st Floor, Tower-1, M3M International Financial center, sector- 66,Gurugram, Haryana, India 122101 | BU20: (……………..)Village Chauma, Sector – 113, Gurugram, Manesar Urban Complex, GURGAON, HARYANA, INDIA PIN Code: 122017 | BV20: Feedback@m3mindia.com | BW20: 8068970077 | BX20: 0 | BY20: Ritika Singh | BZ20: Sabhyata Kapoor
A21: R1 UG 27 | B21: M3M Capital Walk in M3M Capital Phase-1 | C21: WPBOOKING/00012/23-24 | D21: WPFLAP/00018/23-24 | E21: Mr. Amar Chand Gupta | F21: 45183 | G21: BLOCK-01 | H21: BASEMENT 1 | I21: Anchor Units | J21: 391.09 | K21: 391.09 | L21: =K21-J21 -> 0 | M21: 156.08 | N21: 156.08 | O21: =N21-M21 -> 0 | P21: 22435 | Q21: 56215.428 | R21: 28000 | S21: 8774104 | T21: 438706 | U21: =T21/S21 -> 0.050000091 | V21: =L21*P21 -> 0 | W21: =V21*U21 -> 0 | Z21: =S21+V21+X21 -> 8774104 | AC21: =Z21-AA21 -> 8774104 | AD21: =AE21/M21 -> 300 | AE21: 46824 | AF21: 8428 | AG21: =(AD21*O21) -> 0 | AH21: =AG21*18% -> 0 | AI21: =AD21*N21 -> 46824 | AJ21: =ROUNDUP(AI21*18%,0) -> 8429 | AK21: 46824 | AL21: =N21*300 -> 46824 | AM21: =ROUND(AI21+AC21,0) -> 8820928 | AN21: =ROUNDUP(AJ21+W21+T21+Y21-AB21,0) -> 447135 | AO21: =AN21+AL21+AR21 -> 515242 | AP21: =AM21+AO21 -> 9336170 | AQ21: 3724724 | AR21: 21283 | AS21: =ROUND(AP21-AQ21,0) -> 5611446 | AT21: 0 | AU21: 8800 | AV21: =AU21*N21 -> 1373504 | AW21: =MAX(AM21,AT21,AV21) -> 8820928 | AX21: =CEILING((AW21),1000) -> 8821000 | AY21: 0.06 | AZ21: =AY21*AX21 -> 529260 | BA21: =CEILING(AZ21,100) -> 529300 | BB21: =BA21+AS21 -> 6140746 | BC21: =L21/J21% -> 0 | BD21: =O21/M21% -> 0 | BE21: 36.33 | BF21: 14.5 | BG21: 46176 | BH21: =BG21+30 -> 46206 | BI21: 6 | BM21: UBPL M3M CAPITAL MASTER ACCOUNT | BN21: 777705001441 | BO21: ICIC0000399 | BP21: ICICI Bank | BQ21: Shop No - 19, 20, 21, Vipul Orchid Plaza, Suncity, Sector 54, Gurgaon, Haryana -122002 | BR21: Union Buildmart Private Limited | BS21: AABCU4843M | BT21: 41st Floor, Tower-1, M3M International Financial center, sector- 66,Gurugram, Haryana, India 122101 | BU21: (……………..)Village Chauma, Sector – 113, Gurugram, Manesar Urban Complex, GURGAON, HARYANA, INDIA PIN Code: 122017 | BV21: Feedback@m3mindia.com | BW21: 8068970077 | BX21: 0 | BY21: Vidhi Singh | BZ21: Sabhyata Kapoor
A22: R1 248 | B22: M3M Capital Walk in M3M Capital Phase-1 | C22: WPBOOKING/00002/22-23 | D22: WPFLAP/00001/22-23 | E22: Mr. NARESH KUMAR | F22: 44868 | G22: BLOCK-01 | H22: FLOOR 2 | I22: Anchor Units | J22: 477.44 | K22: 477.44 | L22: =K22-J22 -> 0 | M22: 196.98 | N22: 196.98 | O22: =N22-M22 -> 0 | P22: 12962.95 | Q22: 31419.591 | R22: 20000 | S22: 6189031 | T22: 309454 | U22: =T22/S22 -> 0.050000396 | V22: =L22*P22 -> 0 | W22: =V22*U22 -> 0 | Z22: =S22+V22+X22 -> 6189031 | AC22: =Z22-AA22 -> 6189031 | AD22: =AE22/M22 -> 300 | AE22: 59094 | AF22: 10636 | AG22: =(AD22*O22) -> 0 | AH22: =AG22*18% -> 0 | AI22: =AD22*N22 -> 59094 | AJ22: =ROUNDUP(AI22*18%,0) -> 10637 | AK22: 59094 | AL22: =N22*300 -> 59094 | AM22: =ROUND(AI22+AC22,0) -> 6248125 | AN22: =ROUNDUP(AJ22+W22+T22+Y22-AB22,0) -> 320091 | AO22: =AN22+AL22+AR22 -> 398600 | AP22: =AM22+AO22 -> 6646725 | AQ22: 2927888 | AR22: 19415 | AS22: =ROUND(AP22-AQ22,0) -> 3718837 | AT22: 0 | AU22: 8800 | AV22: =AU22*N22 -> 1733424 | AW22: =MAX(AM22,AT22,AV22) -> 6248125 | AX22: =CEILING((AW22),1000) -> 6249000 | AY22: 0.07 | AZ22: =AY22*AX22 -> 437430 | BA22: =CEILING(AZ22,100) -> 437500 | BB22: =BA22+AS22 -> 4156337 | BC22: =L22/J22% -> 0 | BD22: =O22/M22% -> 0 | BE22: 44.36 | BF22: 18.3 | BG22: 46176 | BH22: =BG22+30 -> 46206 | BI22: 7 | BM22: UBPL M3M CAPITAL MASTER ACCOUNT | BN22: 777705001441 | BO22: ICIC0000399 | BP22: ICICI Bank | BQ22: Shop No - 19, 20, 21, Vipul Orchid Plaza, Suncity, Sector 54, Gurgaon, Haryana -122002 | BR22: Union Buildmart Private Limited | BS22: AABCU4843M | BT22: 41st Floor, Tower-1, M3M International Financial center, sector- 66,Gurugram, Haryana, India 122101 | BU22: (……………..)Village Chauma, Sector – 113, Gurugram, Manesar Urban Complex, GURGAON, HARYANA, INDIA PIN Code: 122017 | BV22: Feedback@m3mindia.com | BW22: 8068970077 | BX22: 0 | BY22: Vidhi Singh | BZ22: Sabhyata Kapoor
A23: R2 211 | B23: M3M Capital Walk in M3M Capital Phase-1 | C23: WPBOOKING/00005/23-24 | D23: WPFLAP/00004/23-24 | E23: Ms. RUCHI | F23: 45058 | G23: BLOCK-02 | H23: FLOOR 2 | I23: Retail | J23: 1173.28 | K23: 1190 | L23: =K23-J23 -> 16.72 | M23: 496.22 | N23: 538 | O23: =N23-M23 -> 41.78 | P23: 8972.2402 | Q23: 21214.28 | R23: 20000 | S23: 10526950 | T23: 526348 | U23: =T23/S23 -> 0.050000047 | V23: =L23*R23 -> 334400 | W23: =V23*U23 -> 16720.016 | Z23: =S23+V23+X23 -> 10861350 | AC23: =Z23-AA23 -> 10861350 | AD23: =AE23/M23 -> 300 | AE23: 148866 | AF23: 26796 | AG23: =(AD23*O23) -> 12534 | AH23: =AG23*18% -> 2256.12 | AI23: =AD23*N23 -> 161400 | AJ23: =ROUNDUP(AI23*18%,0) -> 29052 | AK23: 148866 | AL23: =N23*300 -> 161400 | AM23: =ROUND(AI23+AC23,0) -> 11022750 | AN23: =ROUNDUP(AJ23+W23+T23+Y23-AB23,0) -> 572121 | AO23: =AN23+AL23+AR23 -> 756437 | AP23: =AM23+AO23 -> 11779187 | AQ23: 4060786 | AR23: 22916 | AS23: =ROUND(AP23-AQ23,0) -> 7718401 | AT23: 0 | AU23: 8800 | AV23: =AU23*N23 -> 4734400 | AW23: =MAX(AM23,AT23,AV23) -> 11022750 | AX23: =CEILING((AW23),1000) -> 11023000 | AY23: 0.05 | AZ23: =AY23*AX23 -> 551150 | BA23: =CEILING(AZ23,100) -> 551200 | BB23: =BA23+AS23 -> 8269601 | BC23: =L23/J23% -> 1.4250648 | BD23: =O23/M23% -> 8.4196526 | BE23: 110.55 | BF23: 49.98 | BG23: 46176 | BH23: =BG23+30 -> 46206 | BI23: 5 | BM23: UBPL M3M CAPITAL MASTER ACCOUNT | BN23: 777705001441 | BO23: ICIC0000399 | BP23: ICICI Bank | BQ23: Shop No - 19, 20, 21, Vipul Orchid Plaza, Suncity, Sector 54, Gurgaon, Haryana -122002 | BR23: Union Buildmart Private Limited | BS23: AABCU4843M | BT23: 41st Floor, Tower-1, M3M International Financial center, sector- 66,Gurugram, Haryana, India 122101 | BU23: (……………..)Village Chauma, Sector – 113, Gurugram, Manesar Urban Complex, GURGAON, HARYANA, INDIA PIN Code: 122017 | BV23: Feedback@m3mindia.com | BW23: 8068970077 | BX23: 0 | BY23: Ritika Singh | BZ23: Shubra
A24: R2 114 | B24: M3M Capital Walk in M3M Capital Phase-1 | C24: WPBOOKING/00010/23-24 | D24: WPFLAP/00009/23-24 | E24: Mrs. SUKHWINDER DEVI | F24: 45128 | G24: BLOCK-02 | H24: FLOOR 1 | I24: Retail | J24: 847.77 | K24: 900 | L24: =K24-J24 -> 52.23 | M24: 349.83 | N24: 396 | O24: =N24-M24 -> 46.17 | P24: 11790.002 | Q24: 28571.621 | R24: 22000 | S24: 9995210 | T24: 499760 | U24: =T24/S24 -> 0.04999995 | V24: =L24*R24 -> 1149060 | W24: =V24*U24 -> 57452.943 | Z24: =S24+V24+X24 -> 11144270 | AC24: =Z24-AA24 -> 11144270 | AD24: =AE24/M24 -> 300 | AE24: 104949 | AF24: 18890 | AG24: =(AD24*O24) -> 13851 | AH24: =AG24*18% -> 2493.18 | AI24: =AD24*N24 -> 118800 | AJ24: =ROUNDUP(AI24*18%,0) -> 21384 | AK24: 104949 | AL24: =N24*300 -> 118800 | AM24: =ROUND(AI24+AC24,0) -> 11263070 | AN24: =ROUNDUP(AJ24+W24+T24+Y24-AB24,0) -> 578597 | AO24: =AN24+AL24+AR24 -> 728366 | AP24: =AM24+AO24 -> 11991436 | AQ24: 2800000 | AR24: 30969 | AS24: =ROUND(AP24-AQ24,0) -> 9191436 | AT24: 2475000 | AU24: 8800 | AV24: =AU24*N24 -> 3484800 | AW24: =MAX(AM24,AT24,AV24) -> 11263070 | AX24: =CEILING((AW24),1000) -> 11264000 | AY24: 0.05 | AZ24: =AY24*AX24 -> 563200 | BA24: =CEILING(AZ24,100) -> 563200 | BB24: =BA24+AS24 -> 9754636 | BC24: =L24/J24% -> 6.1608691 | BD24: =O24/M24% -> 13.197839 | BE24: 83.61 | BF24: 36.79 | BG24: 46176 | BH24: =BG24+30 -> 46206 | BI24: 5 | BM24: UBPL M3M CAPITAL MASTER ACCOUNT | BN24: 777705001441 | BO24: ICIC0000399 | BP24: ICICI Bank | BQ24: Shop No - 19, 20, 21, Vipul Orchid Plaza, Suncity, Sector 54, Gurgaon, Haryana -122002 | BR24: Union Buildmart Private Limited | BS24: AABCU4843M | BT24: 41st Floor, Tower-1, M3M International Financial center, sector- 66,Gurugram, Haryana, India 122101 | BU24: (……………..)Village Chauma, Sector – 113, Gurugram, Manesar Urban Complex, GURGAON, HARYANA, INDIA PIN Code: 122017 | BV24: Feedback@m3mindia.com | BW24: 8068970077 | BX24: 0 | BY24: Ritika Singh | BZ24: Shubra
A25: R2 UG 20 | B25: M3M Capital Walk in M3M Capital Phase-1 | C25: WPBOOKING/00007/22-23 | D25: WPFLAP/00005/22-23 | E25: Mr. GULAB CHAND CHAURASIA | F25: 44902 | G25: BLOCK-02 | H25: BASEMENT 1 | I25: Retail | J25: 764.24 | K25: 764.24 | L25: =K25-J25 -> 0 | M25: 333.68 | N25: 342 | O25: =N25-M25 -> 8.32 | P25: 17635.84 | Q25: 40392.034 | R25: 28000 | S25: 13478014 | T25: 673900 | U25: =T25/S25 -> 0.049999948 | V25: =L25*P25 -> 0 | W25: =V25*U25 -> 0 | Z25: =S25+V25+X25 -> 13478014 | AC25: =Z25-AA25 -> 13478014 | AD25: =AE25/M25 -> 300 | AE25: 100104 | AF25: 18018 | AG25: =(AD25*O25) -> 2496 | AH25: =AG25*18% -> 449.28 | AI25: =AD25*N25 -> 102600 | AJ25: =ROUNDUP(AI25*18%,0) -> 18468 | AK25: 100104 | AL25: =N25*300 -> 102600 | AM25: =ROUND(AI25+AC25,0) -> 13580614 | AN25: =ROUNDUP(AJ25+W25+T25+Y25-AB25,0) -> 692368 | AO25: =AN25+AL25+AR25 -> 836211.6 | AP25: =AM25+AO25 -> 14416826 | AQ25: 2824279.9 | AR25: 41243.6 | AS25: =ROUND(AP25-AQ25,0) -> 11592546 | AT25: 0 | AU25: 8800 | AV25: =AU25*N25 -> 3009600 | AW25: =MAX(AM25,AT25,AV25) -> 13580614 | AX25: =CEILING((AW25),1000) -> 13581000 | AY25: 0.07 | AZ25: =AY25*AX25 -> 950670 | BA25: =CEILING(AZ25,100) -> 950700 | BB25: =BA25+AS25 -> 12543246 | BC25: =L25/J25% -> 0 | BD25: =O25/M25% -> 2.4934069 | BE25: 71 | BF25: 31.77 | BG25: 46176 | BH25: =BG25+30 -> 46206 | BI25: 7 | BM25: UBPL M3M CAPITAL MASTER ACCOUNT | BN25: 777705001441 | BO25: ICIC0000399 | BP25: ICICI Bank | BQ25: Shop No - 19, 20, 21, Vipul Orchid Plaza, Suncity, Sector 54, Gurgaon, Haryana -122002 | BR25: Union Buildmart Private Limited | BS25: AABCU4843M | BT25: 41st Floor, Tower-1, M3M International Financial center, sector- 66,Gurugram, Haryana, India 122101 | BU25: (……………..)Village Chauma, Sector – 113, Gurugram, Manesar Urban Complex, GURGAON, HARYANA, INDIA PIN Code: 122017 | BV25: Feedback@m3mindia.com | BW25: 8068970077 | BX25: 0 | BY25: Manish Kumar | BZ25: Shubra
A26: R1 261 | B26: M3M Capital Walk in M3M Capital Phase-1 | C26: WPBOOKING/00013/23-24 | D26: WPFLAP/00019/23-24 | E26: Ms. Nirmala Prasad | F26: 45183 | G26: BLOCK-01 | H26: FLOOR 2 | I26: Anchor Units | J26: 2078.65 | K26: 2055 | L26: =K26-J26 -> -23.65 | M26: 785.77 | N26: 833 | O26: =N26-M26 -> 47.23 | P26: 8000.0014 | Q26: 21162.94 | R26: 20000 | S26: 16629203 | T26: 831460 | U26: =T26/S26 -> 0.049999991 | V26: =L26*P26 -> -189200.03 | W26: =V26*U26 -> -9460 | Z26: =S26+V26+X26 -> 16440003 | AC26: =Z26-AA26 -> 16440003 | AD26: =AE26/M26 -> 300 | AE26: 235731 | AF26: 42432 | AG26: =(AD26*O26) -> 14169 | AH26: =AG26*18% -> 2550.42 | AI26: =AD26*N26 -> 249900 | AJ26: =ROUNDUP(AI26*18%,0) -> 44982 | AK26: 235731 | AL26: =N26*300 -> 249900 | AM26: =ROUND(AI26+AC26,0) -> 16689903 | AN26: =ROUNDUP(AJ26+W26+T26+Y26-AB26,0) -> 866982 | AO26: =AN26+AL26+AR26 -> 1154917.3 | AP26: =AM26+AO26 -> 17844820 | AQ26: 9338022.5 | AR26: 38035.26 | AS26: =ROUND(AP26-AQ26,0) -> 8506798 | AT26: 0 | AU26: 8800 | AV26: =AU26*N26 -> 7330400 | AW26: =MAX(AM26,AT26,AV26) -> 16689903 | AX26: =CEILING((AW26),1000) -> 16690000 | AY26: 0.05 | AZ26: =AY26*AX26 -> 834500 | BA26: =CEILING(AZ26,100) -> 834500 | BB26: =BA26+AS26 -> 9341298 | BC26: =L26/J26% -> -1.1377577 | BD26: =O26/M26% -> 6.0106647 | BE26: 190.91 | BF26: 77.39 | BG26: 46176 | BH26: =BG26+30 -> 46206 | BI26: 5 | BM26: UBPL M3M CAPITAL MASTER ACCOUNT | BN26: 777705001441 | BO26: ICIC0000399 | BP26: ICICI Bank | BQ26: Shop No - 19, 20, 21, Vipul Orchid Plaza, Suncity, Sector 54, Gurgaon, Haryana -122002 | BR26: Union Buildmart Private Limited | BS26: AABCU4843M | BT26: 41st Floor, Tower-1, M3M International Financial center, sector- 66,Gurugram, Haryana, India 122101 | BU26: (……………..)Village Chauma, Sector – 113, Gurugram, Manesar Urban Complex, GURGAON, HARYANA, INDIA PIN Code: 122017 | BV26: Feedback@m3mindia.com | BW26: 8068970077 | BX26: 0 | BY26: Manish Kumar | BZ26: Sabhyata Kapoor
A27: R1 247 | B27: M3M Capital Walk in M3M Capital Phase-1 | C27: WPBOOKING/00005/22-23 | D27: WPFLAP/00004/22-23 | E27: Ms. SUMAN KUMARI | F27: 44874 | G27: BLOCK-01 | H27: FLOOR 2 | I27: Anchor Units | J27: 391.09 | K27: 391.09 | L27: =K27-J27 -> 0 | M27: 156.08 | N27: 156.08 | O27: =N27-M27 -> 0 | P27: 13369.999 | Q27: 33501.237 | R27: 20000 | S27: 5228873 | T27: 261444 | U27: =T27/S27 -> 0.050000067 | V27: =L27*P27 -> 0 | W27: =V27*U27 -> 0 | Z27: =S27+V27+X27 -> 5228873 | AC27: =Z27-AA27 -> 5228873 | AD27: =AE27/M27 -> 300 | AE27: 46824 | AF27: 8428 | AG27: =(AD27*O27) -> 0 | AH27: =AG27*18% -> 0 | AI27: =AD27*N27 -> 46824 | AJ27: =ROUNDUP(AI27*18%,0) -> 8429 | AK27: 46824 | AL27: =N27*300 -> 46824 | AM27: =ROUND(AI27+AC27,0) -> 5275697 | AN27: =ROUNDUP(AJ27+W27+T27+Y27-AB27,0) -> 269873 | AO27: =AN27+AL27+AR27 -> 348249 | AP27: =AM27+AO27 -> 5623946 | AQ27: 4941285 | AR27: 31552 | AS27: =ROUND(AP27-AQ27,0) -> 682661 | AT27: 0 | AU27: 8800 | AV27: =AU27*N27 -> 1373504 | AW27: =MAX(AM27,AT27,AV27) -> 5275697 | AX27: =CEILING((AW27),1000) -> 5276000 | AY27: 0.06 | AZ27: =AY27*AX27 -> 316560 | BA27: =CEILING(AZ27,100) -> 316600 | BB27: =BA27+AS27 -> 999261 | BC27: =L27/J27% -> 0 | BD27: =O27/M27% -> 0 | BE27: 36.33 | BF27: 14.5 | BG27: 46176 | BH27: =BG27+30 -> 46206 | BI27: 6 | BM27: UBPL M3M CAPITAL MASTER ACCOUNT | BN27: 777705001441 | BO27: ICIC0000399 | BP27: ICICI Bank | BQ27: Shop No - 19, 20, 21, Vipul Orchid Plaza, Suncity, Sector 54, Gurgaon, Haryana -122002 | BR27: Union Buildmart Private Limited | BS27: AABCU4843M | BT27: 41st Floor, Tower-1, M3M International Financial center, sector- 66,Gurugram, Haryana, India 122101 | BU27: (……………..)Village Chauma, Sector – 113, Gurugram, Manesar Urban Complex, GURGAON, HARYANA, INDIA PIN Code: 122017 | BV27: Feedback@m3mindia.com | BW27: 8068970077 | BX27: 0 | BY27: Priya Anand | BZ27: Sabhyata Kapoor
A28: R2 LG 20 | B28: M3M Capital Walk in M3M Capital Phase-1 | C28: WPBOOKING/00003/24-25 | D28: WPFLAP/00023/23-24 | E28: Mr. Santosh Kumar Aggarwal | F28: 45383 | G28: BLOCK-02 | H28: BASEMENT 2 | I28: Retail | J28: 861 | K28: 861 | L28: =K28-J28 -> 0 | M28: 381 | N28: 381 | O28: =N28-M28 -> 0 | P28: 14730 | Q28: 33287.48 | R28: 40000 | S28: 12682530 | T28: 634128 | U28: =T28/S28 -> 0.050000118 | V28: =L28*P28 -> 0 | W28: =V28*U28 -> 0 | Z28: =S28+V28+X28 -> 12682530 | AC28: =Z28-AA28 -> 12682530 | AD28: =AE28/M28 -> 300 | AE28: 114300 | AF28: 20574 | AG28: =(AD28*O28) -> 0 | AH28: =AG28*18% -> 0 | AI28: =AD28*N28 -> 114300 | AJ28: =ROUNDUP(AI28*18%,0) -> 20574 | AK28: 114300 | AL28: =N28*300 -> 114300 | AM28: =ROUND(AI28+AC28,0) -> 12796830 | AN28: =ROUNDUP(AJ28+W28+T28+Y28-AB28,0) -> 654702 | AO28: =AN28+AL28+AR28 -> 817928 | AP28: =AM28+AO28 -> 13614758 | AQ28: 1485787 | AR28: 48926 | AS28: =ROUND(AP28-AQ28,0) -> 12128971 | AT28: 0 | AU28: 8800 | AV28: =AU28*N28 -> 3352800 | AW28: =MAX(AM28,AT28,AV28) -> 12796830 | AX28: =CEILING((AW28),1000) -> 12797000 | AY28: 0.07 | AZ28: =AY28*AX28 -> 895790 | BA28: =CEILING(AZ28,100) -> 895800 | BB28: =BA28+AS28 -> 13024771 | BC28: =L28/J28% -> 0 | BD28: =O28/M28% -> 0 | BE28: 79.99 | BF28: 35.4 | BG28: 46176 | BH28: =BG28+30 -> 46206 | BI28: 7 | BM28: UBPL M3M CAPITAL MASTER ACCOUNT | BN28: 777705001441 | BO28: ICIC0000399 | BP28: ICICI Bank | BQ28: Shop No - 19, 20, 21, Vipul Orchid Plaza, Suncity, Sector 54, Gurgaon, Haryana -122002 | BR28: Union Buildmart Private Limited | BS28: AABCU4843M | BT28: 41st Floor, Tower-1, M3M International Financial center, sector- 66,Gurugram, Haryana, India 122101 | BU28: (……………..)Village Chauma, Sector – 113, Gurugram, Manesar Urban Complex, GURGAON, HARYANA, INDIA PIN Code: 122017 | BV28: Feedback@m3mindia.com | BW28: 8068970077 | BX28: 0 | BY28: Sudhanshu Gurjar | BZ28: Shubra
A29: R2 LG 18 | B29: M3M Capital Walk in M3M Capital Phase-1 | C29: WPBOOKING/00003/23-24 | D29: WPFLAP/00002/23-24 | E29: Ms. SAROJ BALA | F29: 45055 | G29: BLOCK-02 | H29: BASEMENT 2 | I29: Retail | J29: 955.84 | K29: 1184 | L29: =K29-J29 -> 228.16 | M29: 410.11 | N29: 521 | O29: =N29-M29 -> 110.89 | P29: 21042.566 | Q29: 49043.735 | R29: 40000 | S29: 20113326 | T29: 1005668 | U29: =T29/S29 -> 0.050000085 | V29: =L29*R29 -> 9126400 | W29: =V29*U29 -> 456320.77 | Z29: =S29+V29+X29 -> 29239726 | AC29: =Z29-AA29 -> 29239726 | AD29: =AE29/M29 -> 300 | AE29: 123033 | AF29: 22146 | AG29: =(AD29*O29) -> 33267 | AH29: =AG29*18% -> 5988.06 | AI29: =AD29*N29 -> 156300 | AJ29: =ROUNDUP(AI29*18%,0) -> 28134 | AK29: 123033 | AL29: =N29*300 -> 156300 | AM29: =ROUND(AI29+AC29,0) -> 29396026 | AN29: =ROUNDUP(AJ29+W29+T29+Y29-AB29,0) -> 1490123 | AO29: =AN29+AL29+AR29 -> 1823724.8 | AP29: =AM29+AO29 -> 31219751 | AQ29: 16740764 | AR29: 177301.76 | AS29: =ROUND(AP29-AQ29,0) -> 14478987 | AT29: 0 | AU29: 8800 | AV29: =AU29*N29 -> 4584800 | AW29: =MAX(AM29,AT29,AV29) -> 29396026 | AX29: =CEILING((AW29),1000) -> 29397000 | AY29: 0.05 | AZ29: =AY29*AX29 -> 1469850 | BA29: =CEILING(AZ29,100) -> 1469900 | BB29: =BA29+AS29 -> 15948887 | BC29: =L29/J29% -> 23.870104 | BD29: =O29/M29% -> 27.039087 | BE29: 110 | BF29: 48.4 | BG29: 46176 | BH29: =BG29+30 -> 46206 | BI29: 5 | BM29: UBPL M3M CAPITAL MASTER ACCOUNT | BN29: 777705001441 | BO29: ICIC0000399 | BP29: ICICI Bank | BQ29: Shop No - 19, 20, 21, Vipul Orchid Plaza, Suncity, Sector 54, Gurgaon, Haryana -122002 | BR29: Union Buildmart Private Limited | BS29: AABCU4843M | BT29: 41st Floor, Tower-1, M3M International Financial center, sector- 66,Gurugram, Haryana, India 122101 | BU29: (……………..)Village Chauma, Sector – 113, Gurugram, Manesar Urban Complex, GURGAON, HARYANA, INDIA PIN Code: 122017 | BV29: Feedback@m3mindia.com | BW29: 8068970077 | BX29: 0 | BY29: Manish Kumar | BZ29: Shubra
A30: R1 205 | B30: M3M Capital Walk in M3M Capital Phase-2 | C30: cwBOOKING/00135/22-23 | D30: cwFLAP/00069/22-23 | E30: Mr. KULDEEP KUMAR SHARMA | F30: 44880 | G30: BLOCK-01 | H30: FLOOR 2 | I30: Retail | J30: 369.21 | K30: 369.21 | L30: =K30-J30 -> 0 | M30: 160.38 | N30: 160.38 | O30: =N30-M30 -> 0 | P30: 9040.9604 | Q30: 20813.15 | R30: 20000 | S30: 3338013 | T30: 400562 | U30: =T30/S30 -> 0.12000013 | V30: =L30*P30 -> 0 | W30: =V30*U30 -> 0 | Z30: =S30+V30+X30 -> 3338013 | AA30: 156873 | AB30: 18824 | AC30: =Z30-AA30 -> 3181140 | AD30: =AE30/M30 -> 300 | AE30: 48114 | AF30: 8660 | AG30: =(AD30*O30) -> 0 | AH30: =AG30*18% -> 0 | AI30: =AD30*N30 -> 48114 | AJ30: =ROUNDUP(AI30*18%,0) -> 8661 | AK30: 48114 | AL30: =N30*300 -> 48114 | AM30: =ROUND(AI30+AC30,0) -> 3229254 | AN30: =ROUNDUP(AJ30+W30+T30+Y30-AB30,0) -> 390399 | AO30: =AN30+AL30+AR30 -> 438513 | AP30: =AM30+AO30 -> 3667767 | AQ30: 3188980 | AR30: 0 | AS30: =ROUND(AP30-AQ30,0) -> 478787 | AT30: 0 | AU30: 8800 | AV30: =AU30*N30 -> 1411344 | AW30: =MAX(AM30,AT30,AV30) -> 3229254 | AX30: =CEILING((AW30),1000) -> 3230000 | AY30: 0.07 | AZ30: =AY30*AX30 -> 226100 | BA30: =CEILING(AZ30,100) -> 226100 | BB30: =BA30+AS30 -> 704887 | BC30: =L30/J30% -> 0 | BD30: =O30/M30% -> 0 | BE30: 34.3 | BF30: 14.9 | BG30: 46176 | BH30: =BG30+30 -> 46206 | BI30: 7 | BL30: =VLOOKUP(A30,[2]Sheet1!$D$2:$H$933,5,0) -> 0 | BM30: UBPL M3M CAPITAL PHASE 2 MASTER ACCOUNT | BN30: 777705551661 | BO30: ICIC0000399 | BP30: ICICI Bank | BQ30: Shop No - 19, 20, Vipul Orchid Plaza, Suncity, Sector 54, Gurgaon, Haryana -122002 | BR30: Union Buildmart Private Limited | BS30: AABCU4843M | BT30: 41st Floor, Tower-1, M3M International Financial center, sector- 66,Gurugram, Haryana, India 122101 | BU30: (……………..)Village Chauma, Sector – 113, Gurugram, Manesar Urban Complex, GURGAON, HARYANA, INDIA PIN Code: 122017 | BV30: Feedback@m3mindia.com | BW30: 8068970077 | BX30: 0 | BY30: Sonia Gupta | BZ30: Sabhyata Kapoor
